<?xml version="1.0" ?>
<robot xmlns:xacro="http://www.ros.org/wiki/xacro">
	<xacro:macro name="wheel" params="wheel_name wheel_conector_name tY">
		<!-- tY is Zero if left side, 1 if right side -->
		<link name='${wheel_name}'>
			<collision>
				<origin xyz="0 0 0"	rpy="0 0 0"/>
				<geometry>
					<mesh filename="package://robocol_rover_description/meshes/wheel.dae" scale="${scale_XYZ} ${scale_XYZ} ${scale_XYZ}"/>
				</geometry>
			</collision>
			<visual>
				<origin xyz="0 0 0"	rpy="0 0 0"/>
				<geometry>
					<mesh filename="package://robocol_rover_description/meshes/wheel.dae" scale="${scale_XYZ} ${scale_XYZ} ${scale_XYZ}"/>
				</geometry>
			</visual>
			<inertial>
				<origin xyz="0 0 0" rpy="0 0 0"/>
				<mass value="${wheelMass}"/>
				<xacro:cylinder_inertia m="${wheelMass}" r="${wheelRadius}" h="${wheelWidth}"/>
<!--
				<inertia ixx="${198245.421875*inertia_scale}" ixy="${0.212605*inertia_scale}" ixz="${-0.157506*inertia_scale}" iyy="${108682.085938*inertia_scale}" iyz="${1.189507*inertia_scale}" izz="${108675.554688*inertia_scale}"/>
-->
			</inertial>
		</link>
		<gazebo reference="${wheel_name}">
			<mu1 value="7"/>
			<mu2 value="7"/>
			<kp  value="5.0" />
			<kd>1.0</kd>
			<minDepth>0.0001</minDepth>
			<maxVel>0.0</maxVel>
			<!--kd  value="1.0" />
			<fdir1 value="1 0 0"/-->
		</gazebo>
		<joint name="${wheel_name}_joint" type="continuous">
			<parent link="${wheel_conector_name}"/>
			<child link="${wheel_name}"/>
			<origin xyz="0 0 0" rpy="0 0 ${tY*PI}"/>
			<limit effort="10.0" velocity="100.0"/>
			<axis xyz="1 0 0"/>
			<joint_properties damping="0.0" friction="1.0"/> 
		</joint>
		<transmission name="${wheel_name}_trans">
			<type>transmission_interface/SimpleTransmission</type>
			<joint name="${wheel_name}_joint">
				<hardwareInterface>hardware_interface/EffortJointInterface</hardwareInterface>
			</joint>
			<actuator name="${wheel_name}_Motor">
				<hardwareInterface>hardware_interface/EffortJointInterface</hardwareInterface>
				<mechanicalReduction>1</mechanicalReduction>
			</actuator>
		</transmission>
	</xacro:macro>
</robot>
