<sdf version='1.6'>
  <world name='default'>
    <gravity>0 0 -7</gravity>
    <light name='sun' type='directional'>
      <cast_shadows>1</cast_shadows>
      <pose frame=''>0 0 10 0 -0 0</pose>
      <diffuse>0.8 0.8 0.8 1</diffuse>
      <specular>0.2 0.2 0.2 1</specular>
      <attenuation>
        <range>1000</range>
        <constant>0.9</constant>
        <linear>0.01</linear>
        <quadratic>0.001</quadratic>
      </attenuation>
      <direction>-0.5 0.1 -0.9</direction>
    </light>
    <model name='ground_plane'>
      <static>1</static>
      <link name='link'>
        <collision name='collision'>
          <geometry>
            <plane>
              <normal>0 0 1</normal>
              <size>100 100</size>
            </plane>
          </geometry>
          <surface>
            <contact>
              <collide_bitmask>65535</collide_bitmask>
              <ode/>
            </contact>
            <friction>
              <ode>
                <mu>100</mu>
                <mu2>50</mu2>
              </ode>
              <torsional>
                <ode/>
              </torsional>
            </friction>
            <bounce/>
          </surface>
          <max_contacts>10</max_contacts>
        </collision>
        <visual name='visual'>
          <cast_shadows>0</cast_shadows>
          <geometry>
            <plane>
              <normal>0 0 1</normal>
              <size>100 100</size>
            </plane>
          </geometry>
          <material>
            <script>
              <uri>file://media/materials/scripts/gazebo.material</uri>
              <name>Gazebo/Grey</name>
            </script>
          </material>
        </visual>
        <self_collide>0</self_collide>
        <enable_wind>0</enable_wind>
        <kinematic>0</kinematic>
      </link>
    </model>
    <magnetic_field>6e-06 2.3e-05 -4.2e-05</magnetic_field>
    <atmosphere type='adiabatic'/>
    <physics name='default_physics' default='0' type='ode'>
      <max_step_size>0.001</max_step_size>
      <real_time_factor>1</real_time_factor>
      <real_time_update_rate>1000</real_time_update_rate>
    </physics>
    <scene>
      <ambient>0.4 0.4 0.4 1</ambient>
      <background>0.7 0.7 0.7 1</background>
      <shadows>1</shadows>
    </scene>
    <audio>
      <device>default</device>
    </audio>
    <wind/>
    <spherical_coordinates>
      <surface_model>EARTH_WGS84</surface_model>
      <latitude_deg>0</latitude_deg>
      <longitude_deg>0</longitude_deg>
      <elevation>0</elevation>
      <heading_deg>0</heading_deg>
    </spherical_coordinates>
    <model name='robocol_rover'>
      <link name='base_footprint'>
        <pose frame=''>0 0 0 0 -0 0</pose>
        <inertial>
          <pose frame=''>0 0 0 0 -0 0</pose>
          <mass>8.40001</mass>
          <inertia>
            <ixx>0.146422</ixx>
            <ixy>-9.99999e-08</ixy>
            <ixz>-9.99999e-08</ixz>
            <iyy>0.374952</iyy>
            <iyz>-4e-07</iyz>
            <izz>0.374952</izz>
          </inertia>
        </inertial>
        <collision name='base_footprint_fixed_joint_lump__chassis_collision'>
          <pose frame=''>0 0 0 0 -0 0</pose>
          <geometry>
            <mesh>
              <scale>0.01 0.01 0.01</scale>
              <uri>/home/robocol/catkin_ws/src/robocol_rover_description/meshes/chassis.dae</uri>
            </mesh>
          </geometry>
          <surface>
            <contact>
              <ode/>
            </contact>
            <friction>
              <ode>
                <mu>0.3</mu>
                <mu2>0.3</mu2>
              </ode>
              <torsional>
                <ode/>
              </torsional>
            </friction>
            <bounce/>
          </surface>
          <max_contacts>10</max_contacts>
        </collision>
        <collision name='base_footprint_fixed_joint_lump__camera_link_collision_1'>
          <pose frame=''>0.05 0.2 0.2 0 -0 1.5708</pose>
          <geometry>
            <box>
              <size>0.05 0.05 0.05</size>
            </box>
          </geometry>
          <surface>
            <contact>
              <ode/>
            </contact>
            <friction>
              <ode/>
              <torsional>
                <ode/>
              </torsional>
            </friction>
            <bounce/>
          </surface>
          <max_contacts>10</max_contacts>
        </collision>
        <collision name='base_footprint_fixed_joint_lump__left_rocker_bar_collision_2'>
          <pose frame=''>0.15 0 0 0 -0 0</pose>
          <geometry>
            <mesh>
              <scale>0.01 0.01 0.01</scale>
              <uri>/home/robocol/catkin_ws/src/robocol_rover_description/meshes/chassis_rocker.dae</uri>
            </mesh>
          </geometry>
          <surface>
            <contact>
              <ode/>
            </contact>
            <friction>
              <ode>
                <mu>0.3</mu>
                <mu2>0.3</mu2>
              </ode>
              <torsional>
                <ode/>
              </torsional>
            </friction>
            <bounce/>
          </surface>
          <max_contacts>10</max_contacts>
        </collision>
        <collision name='base_footprint_fixed_joint_lump__right_rocker_bar_collision_3'>
          <pose frame=''>-0.15 0 0 0 -0 -3.14159</pose>
          <geometry>
            <mesh>
              <scale>0.01 0.01 0.01</scale>
              <uri>/home/robocol/catkin_ws/src/robocol_rover_description/meshes/chassis_rocker.dae</uri>
            </mesh>
          </geometry>
          <surface>
            <contact>
              <ode/>
            </contact>
            <friction>
              <ode>
                <mu>0.3</mu>
                <mu2>0.3</mu2>
              </ode>
              <torsional>
                <ode/>
              </torsional>
            </friction>
            <bounce/>
          </surface>
          <max_contacts>10</max_contacts>
        </collision>
        <visual name='base_footprint_fixed_joint_lump__chassis_visual'>
          <pose frame=''>0 0 0 0 -0 0</pose>
          <geometry>
            <mesh>
              <scale>0.01 0.01 0.01</scale>
              <uri>/home/robocol/catkin_ws/src/robocol_rover_description/meshes/chassis.dae</uri>
            </mesh>
          </geometry>
          <material>
            <script>
              <uri>__default__</uri>
              <name>__default__</name>
            </script>
          </material>
        </visual>
        <visual name='base_footprint_fixed_joint_lump__camera_link_visual_1'>
          <pose frame=''>0.05 0.2 0.2 0 -0 1.5708</pose>
          <geometry>
            <box>
              <size>0.05 0.05 0.05</size>
            </box>
          </geometry>
          <material>
            <script>
              <uri>__default__</uri>
              <name>__default__</name>
            </script>
          </material>
        </visual>
        <visual name='base_footprint_fixed_joint_lump__left_rocker_bar_visual_2'>
          <pose frame=''>0.15 0 0 0 -0 0</pose>
          <geometry>
            <mesh>
              <scale>0.01 0.01 0.01</scale>
              <uri>/home/robocol/catkin_ws/src/robocol_rover_description/meshes/chassis_rocker.dae</uri>
            </mesh>
          </geometry>
          <material>
            <script>
              <uri>__default__</uri>
              <name>__default__</name>
            </script>
          </material>
        </visual>
        <visual name='base_footprint_fixed_joint_lump__right_rocker_bar_visual_3'>
          <pose frame=''>-0.15 0 0 0 -0 -3.14159</pose>
          <geometry>
            <mesh>
              <scale>0.01 0.01 0.01</scale>
              <uri>/home/robocol/catkin_ws/src/robocol_rover_description/meshes/chassis_rocker.dae</uri>
            </mesh>
          </geometry>
          <material>
            <script>
              <uri>__default__</uri>
              <name>__default__</name>
            </script>
          </material>
        </visual>
        <velocity_decay/>
        <velocity_decay/>
        <sensor name='camera1' type='camera'>
          <update_rate>30</update_rate>
          <camera name='head'>
            <horizontal_fov>1.39626</horizontal_fov>
            <image>
              <width>800</width>
              <height>800</height>
              <format>R8G8B8</format>
            </image>
            <clip>
              <near>0.02</near>
              <far>300</far>
            </clip>
            <noise>
              <type>gaussian</type>
              <mean>0</mean>
              <stddev>0.007</stddev>
            </noise>
          </camera>
          <plugin name='camera_controller' filename='libgazebo_ros_camera.so'>
            <alwaysOn>1</alwaysOn>
            <updateRate>0.0</updateRate>
            <cameraName>rrbot/camera1</cameraName>
            <imageTopicName>image_raw</imageTopicName>
            <cameraInfoTopicName>camera_info</cameraInfoTopicName>
            <frameName>camera_link</frameName>
            <hackBaseline>0.07</hackBaseline>
            <distortionK1>0.0</distortionK1>
            <distortionK2>0.0</distortionK2>
            <distortionK3>0.0</distortionK3>
            <distortionT1>0.0</distortionT1>
            <distortionT2>0.0</distortionT2>
            <robotNamespace>/</robotNamespace>
          </plugin>
          <pose frame=''>0.05 0.2 0.2 0 -0 1.5708</pose>
        </sensor>
        <velocity_decay/>
        <gravity>1</gravity>
        <velocity_decay/>
        <self_collide>0</self_collide>
        <enable_wind>0</enable_wind>
        <kinematic>0</kinematic>
      </link>
      <link name='left_rocker'>
        <pose frame=''>0.27 0 0 -0.17635 0 0</pose>
        <inertial>
          <pose frame=''>0.0436 0.1372 -0.0784 0 -0 0</pose>
          <mass>2.5</mass>
          <inertia>
            <ixx>0.156165</ixx>
            <ixy>-0.0224322</ixy>
            <ixz>0.0128184</ixz>
            <iyy>0.0712124</iyy>
            <iyz>0.0403368</iyz>
            <izz>0.118762</izz>
          </inertia>
        </inertial>
        <collision name='left_rocker_collision'>
          <pose frame=''>0 0 0 0 -0 0</pose>
          <geometry>
            <mesh>
              <scale>0.01 0.01 0.01</scale>
              <uri>/home/robocol/catkin_ws/src/robocol_rover_description/meshes/rocker_left.dae</uri>
            </mesh>
          </geometry>
          <surface>
            <contact>
              <ode/>
            </contact>
            <friction>
              <ode>
                <mu>0.3</mu>
                <mu2>0.3</mu2>
              </ode>
              <torsional>
                <ode/>
              </torsional>
            </friction>
            <bounce/>
          </surface>
          <max_contacts>10</max_contacts>
        </collision>
        <collision name='left_rocker_to_rear_left_wheel_collision_1'>
          <pose frame=''>0.109 0.343 -0.196 3.14159 1.57079 3.14159</pose>
          <geometry>
            <cylinder>
              <length>0.02</length>
              <radius>0.12</radius>
            </cylinder>
          </geometry>
          <surface>
            <contact>
              <ode/>
            </contact>
            <friction>
              <ode>
                <mu>0.3</mu>
                <mu2>0.3</mu2>
              </ode>
              <torsional>
                <ode/>
              </torsional>
            </friction>
            <bounce/>
          </surface>
          <max_contacts>10</max_contacts>
        </collision>
        <visual name='left_rocker_visual'>
          <pose frame=''>0 0 0 0 -0 0</pose>
          <geometry>
            <mesh>
              <scale>0.01 0.01 0.01</scale>
              <uri>/home/robocol/catkin_ws/src/robocol_rover_description/meshes/rocker_left.dae</uri>
            </mesh>
          </geometry>
          <material>
            <script>
              <uri>__default__</uri>
              <name>__default__</name>
            </script>
          </material>
        </visual>
        <visual name='left_rocker_to_rear_left_wheel_visual_1'>
          <pose frame=''>0.109 0.343 -0.196 3.14159 1.57079 3.14159</pose>
          <geometry>
            <cylinder>
              <length>0.02</length>
              <radius>0.045</radius>
            </cylinder>
          </geometry>
          <material>
            <script>
              <uri>__default__</uri>
              <name>__default__</name>
            </script>
          </material>
        </visual>
        <gravity>1</gravity>
        <velocity_decay/>
        <self_collide>0</self_collide>
        <enable_wind>0</enable_wind>
        <kinematic>0</kinematic>
      </link>
      <joint name='suspension_left_rocker_joint' type='revolute'>
        <child>left_rocker</child>
        <parent>base_footprint</parent>
        <axis>
          <xyz>1 0 0</xyz>
          <limit>
            <lower>-0.4</lower>
            <upper>0.4</upper>
            <effort>10</effort>
            <velocity>10</velocity>
          </limit>
          <dynamics>
            <spring_reference>0</spring_reference>
            <spring_stiffness>0</spring_stiffness>
          </dynamics>
          <use_parent_model_frame>1</use_parent_model_frame>
        </axis>
      </joint>
      <link name='wheel_rear_left'>
        <pose frame=''>0.379 0.303295 -0.253135 -0.17635 0 0</pose>
        <inertial>
          <pose frame=''>0 0 0 0 -0 0</pose>
          <mass>4</mass>
          <inertia>
            <ixx>0.0203289</ixx>
            <ixy>0</ixy>
            <ixz>0</ixz>
            <iyy>0.0203289</iyy>
            <iyz>0</iyz>
            <izz>0.0362882</izz>
          </inertia>
        </inertial>
        <collision name='wheel_rear_left_collision'>
          <pose frame=''>0 0 0 0 -0 0</pose>
          <geometry>
            <mesh>
              <scale>0.01 0.01 0.01</scale>
              <uri>/home/robocol/catkin_ws/src/robocol_rover_description/meshes/wheel.dae</uri>
            </mesh>
          </geometry>
          <surface>
            <contact>
              <ode>
                <kp>1</kp>
                <kd>1</kd>
                <max_vel>1</max_vel>
                <min_depth>0.0001</min_depth>
              </ode>
            </contact>
            <friction>
              <ode>
                <mu>0.5</mu>
                <mu2>0.5</mu2>
              </ode>
              <torsional>
                <ode/>
              </torsional>
            </friction>
            <bounce/>
          </surface>
          <max_contacts>10</max_contacts>
        </collision>
        <visual name='wheel_rear_left_visual'>
          <pose frame=''>0 0 0 0 -0 0</pose>
          <geometry>
            <mesh>
              <scale>0.01 0.01 0.01</scale>
              <uri>/home/robocol/catkin_ws/src/robocol_rover_description/meshes/wheel.dae</uri>
            </mesh>
          </geometry>
          <material>
            <script>
              <uri>__default__</uri>
              <name>__default__</name>
            </script>
          </material>
        </visual>
        <gravity>1</gravity>
        <velocity_decay/>
        <self_collide>0</self_collide>
        <enable_wind>0</enable_wind>
        <kinematic>0</kinematic>
      </link>
      <joint name='wheel_rear_left_joint' type='revolute'>
        <child>wheel_rear_left</child>
        <parent>left_rocker</parent>
        <axis>
          <xyz>1 0 0</xyz>
          <limit>
            <lower>-1e+16</lower>
            <upper>1e+16</upper>
          </limit>
          <dynamics>
            <spring_reference>0</spring_reference>
            <spring_stiffness>0</spring_stiffness>
          </dynamics>
          <use_parent_model_frame>1</use_parent_model_frame>
        </axis>
      </joint>
      <link name='left_boogie'>
        <pose frame=''>0.305 -0.225603 -0.068991 0.04635 -0 -3.14159</pose>
        <inertial>
          <pose frame=''>-0.073333 -0.006667 -0.122333 0 -0 0</pose>
          <mass>3</mass>
          <inertia>
            <ixx>0.112746</ixx>
            <ixy>-0.000733333</ixy>
            <ixz>-0.0134567</ixz>
            <iyy>0.0505504</iyy>
            <iyz>0.00180267</iyz>
            <izz>0.091412</izz>
          </inertia>
        </inertial>
        <collision name='left_boogie_collision'>
          <pose frame=''>0 0 0 0 -0 0</pose>
          <geometry>
            <mesh>
              <scale>0.01 0.01 0.01</scale>
              <uri>/home/robocol/catkin_ws/src/robocol_rover_description/meshes/boogie_left.dae</uri>
            </mesh>
          </geometry>
          <surface>
            <contact>
              <ode/>
            </contact>
            <friction>
              <ode>
                <mu>0.3</mu>
                <mu2>0.3</mu2>
              </ode>
              <torsional>
                <ode/>
              </torsional>
            </friction>
            <bounce/>
          </surface>
          <max_contacts>10</max_contacts>
        </collision>
        <collision name='left_boogie_to_front_left_wheel_collision_1'>
          <pose frame=''>-0.11 0.168 -0.192 3.14159 1.57079 3.14159</pose>
          <geometry>
            <cylinder>
              <length>0.02</length>
              <radius>0.12</radius>
            </cylinder>
          </geometry>
          <surface>
            <contact>
              <ode/>
            </contact>
            <friction>
              <ode>
                <mu>0.3</mu>
                <mu2>0.3</mu2>
              </ode>
              <torsional>
                <ode/>
              </torsional>
            </friction>
            <bounce/>
          </surface>
          <max_contacts>10</max_contacts>
        </collision>
        <collision name='left_boogie_to_middle_left_wheel_collision_2'>
          <pose frame=''>-0.11 -0.188 -0.175 3.14159 1.57079 3.14159</pose>
          <geometry>
            <cylinder>
              <length>0.02</length>
              <radius>0.12</radius>
            </cylinder>
          </geometry>
          <surface>
            <contact>
              <ode/>
            </contact>
            <friction>
              <ode>
                <mu>0.3</mu>
                <mu2>0.3</mu2>
              </ode>
              <torsional>
                <ode/>
              </torsional>
            </friction>
            <bounce/>
          </surface>
          <max_contacts>10</max_contacts>
        </collision>
        <visual name='left_boogie_visual'>
          <pose frame=''>0 0 0 0 -0 0</pose>
          <geometry>
            <mesh>
              <scale>0.01 0.01 0.01</scale>
              <uri>/home/robocol/catkin_ws/src/robocol_rover_description/meshes/boogie_left.dae</uri>
            </mesh>
          </geometry>
          <material>
            <script>
              <uri>__default__</uri>
              <name>__default__</name>
            </script>
          </material>
        </visual>
        <visual name='left_boogie_to_front_left_wheel_visual_1'>
          <pose frame=''>-0.11 0.168 -0.192 3.14159 1.57079 3.14159</pose>
          <geometry>
            <cylinder>
              <length>0.02</length>
              <radius>0.045</radius>
            </cylinder>
          </geometry>
          <material>
            <script>
              <uri>__default__</uri>
              <name>__default__</name>
            </script>
          </material>
        </visual>
        <visual name='left_boogie_to_middle_left_wheel_visual_2'>
          <pose frame=''>-0.11 -0.188 -0.175 3.14159 1.57079 3.14159</pose>
          <geometry>
            <cylinder>
              <length>0.02</length>
              <radius>0.045</radius>
            </cylinder>
          </geometry>
          <material>
            <script>
              <uri>__default__</uri>
              <name>__default__</name>
            </script>
          </material>
        </visual>
        <gravity>1</gravity>
        <velocity_decay/>
        <self_collide>0</self_collide>
        <enable_wind>0</enable_wind>
        <kinematic>0</kinematic>
      </link>
      <joint name='suspension_left_boogie_joint' type='revolute'>
        <child>left_boogie</child>
        <parent>left_rocker</parent>
        <axis>
          <xyz>-1 -0 0</xyz>
          <limit>
            <lower>-0.4</lower>
            <upper>0.4</upper>
            <effort>10</effort>
            <velocity>10</velocity>
          </limit>
          <dynamics>
            <spring_reference>0</spring_reference>
            <spring_stiffness>0</spring_stiffness>
          </dynamics>
          <use_parent_model_frame>1</use_parent_model_frame>
        </axis>
      </joint>
      <link name='wheel_front_left'>
        <pose frame=''>0.415 -0.402318 -0.253001 0.04635 -0 -3.14159</pose>
        <inertial>
          <pose frame=''>0 0 0 0 -0 0</pose>
          <mass>4</mass>
          <inertia>
            <ixx>0.0203289</ixx>
            <ixy>0</ixy>
            <ixz>0</ixz>
            <iyy>0.0203289</iyy>
            <iyz>0</iyz>
            <izz>0.0362882</izz>
          </inertia>
        </inertial>
        <collision name='wheel_front_left_collision'>
          <pose frame=''>0 0 0 0 -0 0</pose>
          <geometry>
            <mesh>
              <scale>0.01 0.01 0.01</scale>
              <uri>/home/robocol/catkin_ws/src/robocol_rover_description/meshes/wheel.dae</uri>
            </mesh>
          </geometry>
          <surface>
            <contact>
              <ode>
                <kp>1</kp>
                <kd>1</kd>
                <max_vel>1</max_vel>
                <min_depth>0.0001</min_depth>
              </ode>
            </contact>
            <friction>
              <ode>
                <mu>0.5</mu>
                <mu2>0.5</mu2>
              </ode>
              <torsional>
                <ode/>
              </torsional>
            </friction>
            <bounce/>
          </surface>
          <max_contacts>10</max_contacts>
        </collision>
        <visual name='wheel_front_left_visual'>
          <pose frame=''>0 0 0 0 -0 0</pose>
          <geometry>
            <mesh>
              <scale>0.01 0.01 0.01</scale>
              <uri>/home/robocol/catkin_ws/src/robocol_rover_description/meshes/wheel.dae</uri>
            </mesh>
          </geometry>
          <material>
            <script>
              <uri>__default__</uri>
              <name>__default__</name>
            </script>
          </material>
        </visual>
        <gravity>1</gravity>
        <velocity_decay/>
        <self_collide>0</self_collide>
        <enable_wind>0</enable_wind>
        <kinematic>0</kinematic>
      </link>
      <joint name='wheel_front_left_joint' type='revolute'>
        <child>wheel_front_left</child>
        <parent>left_boogie</parent>
        <axis>
          <xyz>-1 -0 0</xyz>
          <limit>
            <lower>-1e+16</lower>
            <upper>1e+16</upper>
          </limit>
          <dynamics>
            <spring_reference>0</spring_reference>
            <spring_stiffness>0</spring_stiffness>
          </dynamics>
          <use_parent_model_frame>1</use_parent_model_frame>
        </axis>
      </joint>
      <link name='wheel_middle_left'>
        <pose frame=''>0.415 -0.045913 -0.252514 0.04635 -0 -3.14159</pose>
        <inertial>
          <pose frame=''>0 0 0 0 -0 0</pose>
          <mass>4</mass>
          <inertia>
            <ixx>0.0203289</ixx>
            <ixy>0</ixy>
            <ixz>0</ixz>
            <iyy>0.0203289</iyy>
            <iyz>0</iyz>
            <izz>0.0362882</izz>
          </inertia>
        </inertial>
        <collision name='wheel_middle_left_collision'>
          <pose frame=''>0 0 0 0 -0 0</pose>
          <geometry>
            <mesh>
              <scale>0.01 0.01 0.01</scale>
              <uri>/home/robocol/catkin_ws/src/robocol_rover_description/meshes/wheel.dae</uri>
            </mesh>
          </geometry>
          <surface>
            <contact>
              <ode>
                <kp>1</kp>
                <kd>1</kd>
                <max_vel>1</max_vel>
                <min_depth>0.0001</min_depth>
              </ode>
            </contact>
            <friction>
              <ode>
                <mu>0.5</mu>
                <mu2>0.5</mu2>
              </ode>
              <torsional>
                <ode/>
              </torsional>
            </friction>
            <bounce/>
          </surface>
          <max_contacts>10</max_contacts>
        </collision>
        <visual name='wheel_middle_left_visual'>
          <pose frame=''>0 0 0 0 -0 0</pose>
          <geometry>
            <mesh>
              <scale>0.01 0.01 0.01</scale>
              <uri>/home/robocol/catkin_ws/src/robocol_rover_description/meshes/wheel.dae</uri>
            </mesh>
          </geometry>
          <material>
            <script>
              <uri>__default__</uri>
              <name>__default__</name>
            </script>
          </material>
        </visual>
        <gravity>1</gravity>
        <velocity_decay/>
        <self_collide>0</self_collide>
        <enable_wind>0</enable_wind>
        <kinematic>0</kinematic>
      </link>
      <joint name='wheel_middle_left_joint' type='revolute'>
        <child>wheel_middle_left</child>
        <parent>left_boogie</parent>
        <axis>
          <xyz>-1 -0 0</xyz>
          <limit>
            <lower>-1e+16</lower>
            <upper>1e+16</upper>
          </limit>
          <dynamics>
            <spring_reference>0</spring_reference>
            <spring_stiffness>0</spring_stiffness>
          </dynamics>
          <use_parent_model_frame>1</use_parent_model_frame>
        </axis>
      </joint>
      <link name='right_rocker'>
        <pose frame=''>-0.27 -0 0 -0.17635 -0 0</pose>
        <inertial>
          <pose frame=''>-0.0436 0.1372 -0.0784 0 -0 0</pose>
          <mass>2.5</mass>
          <inertia>
            <ixx>0.156165</ixx>
            <ixy>0.0224322</ixy>
            <ixz>-0.0128184</ixz>
            <iyy>0.0712124</iyy>
            <iyz>0.0403368</iyz>
            <izz>0.118762</izz>
          </inertia>
        </inertial>
        <collision name='right_rocker_collision'>
          <pose frame=''>0 0 0 0 -0 0</pose>
          <geometry>
            <mesh>
              <scale>0.01 0.01 0.01</scale>
              <uri>/home/robocol/catkin_ws/src/robocol_rover_description/meshes/rocker_right.dae</uri>
            </mesh>
          </geometry>
          <surface>
            <contact>
              <ode/>
            </contact>
            <friction>
              <ode>
                <mu>0.3</mu>
                <mu2>0.3</mu2>
              </ode>
              <torsional>
                <ode/>
              </torsional>
            </friction>
            <bounce/>
          </surface>
          <max_contacts>10</max_contacts>
        </collision>
        <collision name='right_rocker_to_rear_right_wheel_collision_1'>
          <pose frame=''>-0.109 0.343 -0.196 3.14159 1.57079 3.14159</pose>
          <geometry>
            <cylinder>
              <length>0.02</length>
              <radius>0.12</radius>
            </cylinder>
          </geometry>
          <surface>
            <contact>
              <ode/>
            </contact>
            <friction>
              <ode>
                <mu>0.3</mu>
                <mu2>0.3</mu2>
              </ode>
              <torsional>
                <ode/>
              </torsional>
            </friction>
            <bounce/>
          </surface>
          <max_contacts>10</max_contacts>
        </collision>
        <visual name='right_rocker_visual'>
          <pose frame=''>0 0 0 0 -0 0</pose>
          <geometry>
            <mesh>
              <scale>0.01 0.01 0.01</scale>
              <uri>/home/robocol/catkin_ws/src/robocol_rover_description/meshes/rocker_right.dae</uri>
            </mesh>
          </geometry>
          <material>
            <script>
              <uri>__default__</uri>
              <name>__default__</name>
            </script>
          </material>
        </visual>
        <visual name='right_rocker_to_rear_right_wheel_visual_1'>
          <pose frame=''>-0.109 0.343 -0.196 3.14159 1.57079 3.14159</pose>
          <geometry>
            <cylinder>
              <length>0.02</length>
              <radius>0.045</radius>
            </cylinder>
          </geometry>
          <material>
            <script>
              <uri>__default__</uri>
              <name>__default__</name>
            </script>
          </material>
        </visual>
        <gravity>1</gravity>
        <velocity_decay/>
        <self_collide>0</self_collide>
        <enable_wind>0</enable_wind>
        <kinematic>0</kinematic>
      </link>
      <joint name='suspension_right_rocker_joint' type='revolute'>
        <child>right_rocker</child>
        <parent>base_footprint</parent>
        <axis>
          <xyz>1 0 0</xyz>
          <limit>
            <lower>-0.4</lower>
            <upper>0.4</upper>
            <effort>10</effort>
            <velocity>10</velocity>
          </limit>
          <dynamics>
            <spring_reference>0</spring_reference>
            <spring_stiffness>0</spring_stiffness>
          </dynamics>
          <use_parent_model_frame>1</use_parent_model_frame>
        </axis>
      </joint>
      <link name='wheel_rear_right'>
        <pose frame=''>-0.379 0.303295 -0.253135 -0.17635 -0 0</pose>
        <inertial>
          <pose frame=''>0 0 0 0 -0 0</pose>
          <mass>4</mass>
          <inertia>
            <ixx>0.0203289</ixx>
            <ixy>0</ixy>
            <ixz>0</ixz>
            <iyy>0.0203289</iyy>
            <iyz>0</iyz>
            <izz>0.0362882</izz>
          </inertia>
        </inertial>
        <collision name='wheel_rear_right_collision'>
          <pose frame=''>0 0 0 0 -0 0</pose>
          <geometry>
            <mesh>
              <scale>0.01 0.01 0.01</scale>
              <uri>/home/robocol/catkin_ws/src/robocol_rover_description/meshes/wheel.dae</uri>
            </mesh>
          </geometry>
          <surface>
            <contact>
              <ode>
                <kp>1</kp>
                <kd>1</kd>
                <max_vel>1</max_vel>
                <min_depth>0.0001</min_depth>
              </ode>
            </contact>
            <friction>
              <ode>
                <mu>0.5</mu>
                <mu2>0.5</mu2>
              </ode>
              <torsional>
                <ode/>
              </torsional>
            </friction>
            <bounce/>
          </surface>
          <max_contacts>10</max_contacts>
        </collision>
        <visual name='wheel_rear_right_visual'>
          <pose frame=''>0 0 0 0 -0 0</pose>
          <geometry>
            <mesh>
              <scale>0.01 0.01 0.01</scale>
              <uri>/home/robocol/catkin_ws/src/robocol_rover_description/meshes/wheel.dae</uri>
            </mesh>
          </geometry>
          <material>
            <script>
              <uri>__default__</uri>
              <name>__default__</name>
            </script>
          </material>
        </visual>
        <gravity>1</gravity>
        <velocity_decay/>
        <self_collide>0</self_collide>
        <enable_wind>0</enable_wind>
        <kinematic>0</kinematic>
      </link>
      <joint name='wheel_rear_right_joint' type='revolute'>
        <child>wheel_rear_right</child>
        <parent>right_rocker</parent>
        <axis>
          <xyz>1 0 0</xyz>
          <limit>
            <lower>-1e+16</lower>
            <upper>1e+16</upper>
          </limit>
          <dynamics>
            <spring_reference>0</spring_reference>
            <spring_stiffness>0</spring_stiffness>
          </dynamics>
          <use_parent_model_frame>1</use_parent_model_frame>
        </axis>
      </joint>
      <link name='right_boogie'>
        <pose frame=''>-0.305 -0.225603 -0.068991 -0.04635 -0 0</pose>
        <inertial>
          <pose frame=''>-0.073333 0.006667 -0.122333 0 -0 0</pose>
          <mass>3</mass>
          <inertia>
            <ixx>0.112746</ixx>
            <ixy>0.000733333</ixy>
            <ixz>-0.0134567</ixz>
            <iyy>0.0505504</iyy>
            <iyz>-0.00180267</iyz>
            <izz>0.091412</izz>
          </inertia>
        </inertial>
        <collision name='right_boogie_collision'>
          <pose frame=''>0 0 0 0 -0 0</pose>
          <geometry>
            <mesh>
              <scale>0.01 0.01 0.01</scale>
              <uri>/home/robocol/catkin_ws/src/robocol_rover_description/meshes/boogie_right.dae</uri>
            </mesh>
          </geometry>
          <surface>
            <contact>
              <ode/>
            </contact>
            <friction>
              <ode>
                <mu>0.3</mu>
                <mu2>0.3</mu2>
              </ode>
              <torsional>
                <ode/>
              </torsional>
            </friction>
            <bounce/>
          </surface>
          <max_contacts>10</max_contacts>
        </collision>
        <collision name='right_boogie_to_front_right_wheel_collision_1'>
          <pose frame=''>-0.11 -0.168 -0.192 3.14159 1.57079 3.14159</pose>
          <geometry>
            <cylinder>
              <length>0.02</length>
              <radius>0.12</radius>
            </cylinder>
          </geometry>
          <surface>
            <contact>
              <ode/>
            </contact>
            <friction>
              <ode>
                <mu>0.3</mu>
                <mu2>0.3</mu2>
              </ode>
              <torsional>
                <ode/>
              </torsional>
            </friction>
            <bounce/>
          </surface>
          <max_contacts>10</max_contacts>
        </collision>
        <collision name='right_boogie_to_middle_right_wheel_collision_2'>
          <pose frame=''>-0.11 0.188 -0.175 3.14159 1.57079 3.14159</pose>
          <geometry>
            <cylinder>
              <length>0.02</length>
              <radius>0.12</radius>
            </cylinder>
          </geometry>
          <surface>
            <contact>
              <ode/>
            </contact>
            <friction>
              <ode>
                <mu>0.3</mu>
                <mu2>0.3</mu2>
              </ode>
              <torsional>
                <ode/>
              </torsional>
            </friction>
            <bounce/>
          </surface>
          <max_contacts>10</max_contacts>
        </collision>
        <visual name='right_boogie_visual'>
          <pose frame=''>0 0 0 0 -0 0</pose>
          <geometry>
            <mesh>
              <scale>0.01 0.01 0.01</scale>
              <uri>/home/robocol/catkin_ws/src/robocol_rover_description/meshes/boogie_right.dae</uri>
            </mesh>
          </geometry>
          <material>
            <script>
              <uri>__default__</uri>
              <name>__default__</name>
            </script>
          </material>
        </visual>
        <visual name='right_boogie_to_front_right_wheel_visual_1'>
          <pose frame=''>-0.11 -0.168 -0.192 3.14159 1.57079 3.14159</pose>
          <geometry>
            <cylinder>
              <length>0.02</length>
              <radius>0.045</radius>
            </cylinder>
          </geometry>
          <material>
            <script>
              <uri>__default__</uri>
              <name>__default__</name>
            </script>
          </material>
        </visual>
        <visual name='right_boogie_to_middle_right_wheel_visual_2'>
          <pose frame=''>-0.11 0.188 -0.175 3.14159 1.57079 3.14159</pose>
          <geometry>
            <cylinder>
              <length>0.02</length>
              <radius>0.045</radius>
            </cylinder>
          </geometry>
          <material>
            <script>
              <uri>__default__</uri>
              <name>__default__</name>
            </script>
          </material>
        </visual>
        <gravity>1</gravity>
        <velocity_decay/>
        <self_collide>0</self_collide>
        <enable_wind>0</enable_wind>
        <kinematic>0</kinematic>
      </link>
      <joint name='suspension_right_boogie_joint' type='revolute'>
        <child>right_boogie</child>
        <parent>right_rocker</parent>
        <axis>
          <xyz>1 0 0</xyz>
          <limit>
            <lower>-0.4</lower>
            <upper>0.4</upper>
            <effort>10</effort>
            <velocity>10</velocity>
          </limit>
          <dynamics>
            <spring_reference>0</spring_reference>
            <spring_stiffness>0</spring_stiffness>
          </dynamics>
          <use_parent_model_frame>1</use_parent_model_frame>
        </axis>
      </joint>
      <link name='wheel_front_right'>
        <pose frame=''>-0.415 -0.402318 -0.253001 -0.04635 -0 0</pose>
        <inertial>
          <pose frame=''>0 0 0 0 -0 0</pose>
          <mass>4</mass>
          <inertia>
            <ixx>0.0203289</ixx>
            <ixy>0</ixy>
            <ixz>0</ixz>
            <iyy>0.0203289</iyy>
            <iyz>0</iyz>
            <izz>0.0362882</izz>
          </inertia>
        </inertial>
        <collision name='wheel_front_right_collision'>
          <pose frame=''>0 0 0 0 -0 0</pose>
          <geometry>
            <mesh>
              <scale>0.01 0.01 0.01</scale>
              <uri>/home/robocol/catkin_ws/src/robocol_rover_description/meshes/wheel.dae</uri>
            </mesh>
          </geometry>
          <surface>
            <contact>
              <ode>
                <kp>1</kp>
                <kd>1</kd>
                <max_vel>1</max_vel>
                <min_depth>0.0001</min_depth>
              </ode>
            </contact>
            <friction>
              <ode>
                <mu>0.5</mu>
                <mu2>0.5</mu2>
              </ode>
              <torsional>
                <ode/>
              </torsional>
            </friction>
            <bounce/>
          </surface>
          <max_contacts>10</max_contacts>
        </collision>
        <visual name='wheel_front_right_visual'>
          <pose frame=''>0 0 0 0 -0 0</pose>
          <geometry>
            <mesh>
              <scale>0.01 0.01 0.01</scale>
              <uri>/home/robocol/catkin_ws/src/robocol_rover_description/meshes/wheel.dae</uri>
            </mesh>
          </geometry>
          <material>
            <script>
              <uri>__default__</uri>
              <name>__default__</name>
            </script>
          </material>
        </visual>
        <gravity>1</gravity>
        <velocity_decay/>
        <self_collide>0</self_collide>
        <enable_wind>0</enable_wind>
        <kinematic>0</kinematic>
      </link>
      <joint name='wheel_front_right_joint' type='revolute'>
        <child>wheel_front_right</child>
        <parent>right_boogie</parent>
        <axis>
          <xyz>1 0 0</xyz>
          <limit>
            <lower>-1e+16</lower>
            <upper>1e+16</upper>
          </limit>
          <dynamics>
            <spring_reference>0</spring_reference>
            <spring_stiffness>0</spring_stiffness>
          </dynamics>
          <use_parent_model_frame>1</use_parent_model_frame>
        </axis>
      </joint>
      <link name='wheel_middle_right'>
        <pose frame=''>-0.415 -0.045913 -0.252514 -0.04635 -0 0</pose>
        <inertial>
          <pose frame=''>0 0 0 0 -0 0</pose>
          <mass>4</mass>
          <inertia>
            <ixx>0.0203289</ixx>
            <ixy>0</ixy>
            <ixz>0</ixz>
            <iyy>0.0203289</iyy>
            <iyz>0</iyz>
            <izz>0.0362882</izz>
          </inertia>
        </inertial>
        <collision name='wheel_middle_right_collision'>
          <pose frame=''>0 0 0 0 -0 0</pose>
          <geometry>
            <mesh>
              <scale>0.01 0.01 0.01</scale>
              <uri>/home/robocol/catkin_ws/src/robocol_rover_description/meshes/wheel.dae</uri>
            </mesh>
          </geometry>
          <surface>
            <contact>
              <ode>
                <kp>1</kp>
                <kd>1</kd>
                <max_vel>1</max_vel>
                <min_depth>0.0001</min_depth>
              </ode>
            </contact>
            <friction>
              <ode>
                <mu>0.5</mu>
                <mu2>0.5</mu2>
              </ode>
              <torsional>
                <ode/>
              </torsional>
            </friction>
            <bounce/>
          </surface>
          <max_contacts>10</max_contacts>
        </collision>
        <visual name='wheel_middle_right_visual'>
          <pose frame=''>0 0 0 0 -0 0</pose>
          <geometry>
            <mesh>
              <scale>0.01 0.01 0.01</scale>
              <uri>/home/robocol/catkin_ws/src/robocol_rover_description/meshes/wheel.dae</uri>
            </mesh>
          </geometry>
          <material>
            <script>
              <uri>__default__</uri>
              <name>__default__</name>
            </script>
          </material>
        </visual>
        <gravity>1</gravity>
        <velocity_decay/>
        <self_collide>0</self_collide>
        <enable_wind>0</enable_wind>
        <kinematic>0</kinematic>
      </link>
      <joint name='wheel_middle_right_joint' type='revolute'>
        <child>wheel_middle_right</child>
        <parent>right_boogie</parent>
        <axis>
          <xyz>1 0 0</xyz>
          <limit>
            <lower>-1e+16</lower>
            <upper>1e+16</upper>
          </limit>
          <dynamics>
            <spring_reference>0</spring_reference>
            <spring_stiffness>0</spring_stiffness>
          </dynamics>
          <use_parent_model_frame>1</use_parent_model_frame>
        </axis>
      </joint>
      <plugin name='gazebo_ros_control' filename='libgazebo_ros_control.so'>
        <robotNamespace>/robocol_rover</robotNamespace>
        <robotParam>/robot_description</robotParam>
        <robotSimType>gazebo_ros_control/DefaultRobotHWSim</robotSimType>
      </plugin>
      <static>0</static>
      <plugin name='ground_truth' filename='libgazebo_ros_p3d.so'>
        <frameName>world</frameName>
        <topicName>/robocol_rover/odom</topicName>
        <updateRate>30.0</updateRate>
        <robotNamespace>/</robotNamespace>
        <bodyName>base_footprint</bodyName>
        <xyzOffset>0 0 0</xyzOffset>
        <rpyOffset>0 -0 0</rpyOffset>
      </plugin>
      <pose frame=''>0 0 2 0 -0 0</pose>
    </model>
    <model name='school'>
      <static>1</static>
      <link name='link'>
        <collision name='collision'>
          <geometry>
            <mesh>
              <uri>model://school/meshes/school.dae</uri>
            </mesh>
          </geometry>
          <max_contacts>10</max_contacts>
          <surface>
            <contact>
              <ode/>
            </contact>
            <bounce/>
            <friction>
              <torsional>
                <ode/>
              </torsional>
              <ode/>
            </friction>
          </surface>
        </collision>
        <visual name='visual'>
          <geometry>
            <mesh>
              <uri>model://school/meshes/school.dae</uri>
            </mesh>
          </geometry>
        </visual>
        <self_collide>0</self_collide>
        <enable_wind>0</enable_wind>
        <kinematic>0</kinematic>
      </link>
      <pose frame=''>-1.64294 18.8265 0 0 -0 0</pose>
    </model>
    <state world_name='default'>
      <sim_time>23 128000000</sim_time>
      <real_time>72 199222528</real_time>
      <wall_time>1589253607 771526689</wall_time>
      <iterations>23128</iterations>
      <model name='ground_plane'>
        <pose frame=''>0 0 0 0 -0 0</pose>
        <scale>1 1 1</scale>
        <link name='link'>
          <pose frame=''>0 0 0 0 -0 0</pose>
          <velocity>0 0 0 0 -0 0</velocity>
          <acceleration>0 0 0 0 -0 0</acceleration>
          <wrench>0 0 0 0 -0 0</wrench>
        </link>
      </model>
      <model name='robocol_rover'>
        <pose frame=''>0.000217 -0.030301 0.372918 -0.01296 3e-06 -0.001372</pose>
        <scale>1 1 1</scale>
        <link name='base_footprint'>
          <pose frame=''>0.000217 -0.030301 0.372918 -0.01296 3e-06 -0.001372</pose>
          <velocity>0.000424 -0.000603 -0.00178 -0.001135 0.002868 0.003127</velocity>
          <acceleration>0.537125 -0.116301 -1.5797 3.13905 -0.054723 0.425453</acceleration>
          <wrench>4.51185 -0.976929 -13.2695 0 -0 0</wrench>
        </link>
        <link name='left_boogie'>
          <pose frame=''>0.304906 -0.256274 0.303769 0.047715 -8e-06 3.14022</pose>
          <velocity>0.000995 -0.000306 0.000554 0.000879 0.003296 0.0003</velocity>
          <acceleration>0.698167 0.334311 0.102073 0.937435 -0.701495 -2.03249</acceleration>
          <wrench>2.0945 1.00293 0.30622 0 -0 0</wrench>
        </link>
        <link name='left_rocker'>
          <pose frame=''>0.270216 -0.030671 0.372918 -0.175652 8e-06 -0.001375</pose>
          <velocity>0.000447 0.000353 -0.002581 -0.013904 0.002519 0.002555</velocity>
          <acceleration>-0.219325 -0.570764 -4.30635 0.446038 0.753328 1.25618</acceleration>
          <wrench>-0.548312 -1.42691 -10.7659 0 -0 0</wrench>
        </link>
        <link name='right_boogie'>
          <pose frame=''>-0.305091 -0.255436 0.303767 -0.047707 -3e-06 -0.001369</pose>
          <velocity>0.001028 -0.001434 -0.001546 0.012683 0.001979 0.002407</velocity>
          <acceleration>1.11497 0.597822 -0.909015 0.022272 1.40436 0.296669</acceleration>
          <wrench>3.3449 1.79347 -2.72704 0 -0 0</wrench>
        </link>
        <link name='right_rocker'>
          <pose frame=''>-0.269783 -0.029931 0.372919 -0.175636 -0 -0.001372</pose>
          <velocity>0.000304 -0.001232 -0.001273 0.004197 0.003616 0.003018</velocity>
          <acceleration>-0.34145 -0.692844 -0.397164 0.687284 1.04231 1.53563</acceleration>
          <wrench>-0.853624 -1.73211 -0.992911 0 -0 0</wrench>
        </link>
        <link name='wheel_front_left'>
          <pose frame=''>0.414661 -0.433391 0.12 -0.013807 -4e-06 3.14022</pose>
          <velocity>0.000996 -0.00028 0.000202 0.002933 0.002593 0.002839</velocity>
          <acceleration>1.07412 -0.148702 0.645874 -3.10455 -0.139696 0.144525</acceleration>
          <wrench>4.29646 -0.594809 2.5835 0 -0 0</wrench>
        </link>
        <link name='wheel_front_right'>
          <pose frame=''>-0.415333 -0.43225 0.119996 0.031112 -2e-06 -0.001369</pose>
          <velocity>0.001088 0.0006 -0.003578 0.00349 0.002711 0.003034</velocity>
          <acceleration>1.54939 1.36939 -3.61643 2.40549 0.553814 0.670081</acceleration>
          <wrench>6.19755 5.47756 -14.4657 0 -0 0</wrench>
        </link>
        <link name='wheel_middle_left'>
          <pose frame=''>0.415152 -0.076986 0.12 -0.021891 -4e-06 3.14022</pose>
          <velocity>-1.6e-05 -0.000266 0.000251 0.00322 0.002633 0.002803</velocity>
          <acceleration>-0.071935 -0.142482 -0.491114 2.90511 -0.353677 0.034033</acceleration>
          <wrench>-0.28774 -0.569927 -1.96446 0 -0 0</wrench>
        </link>
        <link name='wheel_middle_right'>
          <pose frame=''>-0.414845 -0.075845 0.12 0.031625 -2e-06 -0.001369</pose>
          <velocity>1.1e-05 0.00062 0.001017 0.003278 0.002691 0.003067</velocity>
          <acceleration>0.207707 1.38869 2.00142 2.66447 0.581962 0.734487</acceleration>
          <wrench>0.830828 5.55478 8.00569 0 -0 0</wrench>
        </link>
        <link name='wheel_rear_left'>
          <pose frame=''>0.379632 0.27265 0.119994 -0.084489 6e-06 -0.001376</pose>
          <velocity>-0.001139 -0.002919 -0.007106 0.004412 0.003006 0.00265</velocity>
          <acceleration>-1.35515 -2.10084 -7.09935 -2.52165 -0.483859 -0.069759</acceleration>
          <wrench>-5.42062 -8.40334 -28.3974 0 -0 0</wrench>
        </link>
        <link name='wheel_rear_right'>
          <pose frame=''>-0.378366 0.273695 0.120001 -0.090517 -1e-06 -0.001369</pose>
          <velocity>-0.001355 -0.001069 0.000206 0.004335 0.002989 0.003306</velocity>
          <acceleration>-1.4082 -0.968922 0.261788 -3.08048 0.535953 0.810269</acceleration>
          <wrench>-5.63279 -3.87569 1.04715 0 -0 0</wrench>
        </link>
      </model>
      <model name='school'>
        <pose frame=''>-1.64294 18.8265 0 0 -0 0</pose>
        <scale>1 1 1</scale>
        <link name='link'>
          <pose frame=''>-1.64294 18.8265 0 0 -0 0</pose>
          <velocity>0 0 0 0 -0 0</velocity>
          <acceleration>0 0 0 0 -0 0</acceleration>
          <wrench>0 0 0 0 -0 0</wrench>
        </link>
      </model>
      <light name='sun'>
        <pose frame=''>0 0 10 0 -0 0</pose>
      </light>
    </state>
    <gui fullscreen='0'>
      <camera name='user_camera'>
        <pose frame=''>5 -5 2 0 0.275643 2.35619</pose>
        <view_controller>orbit</view_controller>
        <projection_type>perspective</projection_type>
      </camera>
    </gui>
  </world>
</sdf>
